Workbook

Sheet Dashboard
B2: Pharmacy Operations Control Dashboard
B3: Real-time clinical metrics & financial summary (KES)
B5: Total Stock Valuation | E5: Total Items Tracked | H5: Active Expiry Alerts | K5: Low Stock Reorder Alerts
B6: ='Master Inventory'!H445 -> 129478 | E6: =COUNTA('Master Inventory'!D5:D300) -> 295 | H6: =COUNTIF('Expiry Register'!J5:J300, "*EXPIRED*") -> 0 | K6: =COUNTIF('Master Inventory'!N5:N300, "*REORDER*") -> 0
B9: Inventory Category Analytics Matrix
B11: Category Profile | C11: Line Items Managed | D11: Reorder Flags
B12: Analgesic Injection | C12: =COUNTIF('Master Inventory'!C5:C444, "Analgesic Injection") -> 5 | D12: =COUNTIFS('Master Inventory'!C5:C300, "Analgesic Injection", 'Master Inventory'!N5:N300, "*REORDER*") -> 0
B13: Analgesic Syrup | C13: =COUNTIF('Master Inventory'!C5:C444, "Analgesic Syrup") -> 15 | D13: =COUNTIFS('Master Inventory'!C5:C300, "Analgesic Syrup", 'Master Inventory'!N5:N300, "*REORDER*") -> 0
B14: Antacids | C14: =COUNTIF('Master Inventory'!C5:C444, "Antacids") -> 20 | D14: =COUNTIFS('Master Inventory'!C5:C300, "Antacids", 'Master Inventory'!N5:N300, "*REORDER*") -> 0
B15: Anti Amoeba | C15: =COUNTIF('Master Inventory'!C5:C444, "Anti Amoeba") -> 12 | D15: =COUNTIFS('Master Inventory'!C5:C300, "Anti Amoeba", 'Master Inventory'!N5:N300, "*REORDER*") -> 0
B16: Anti Hypertensives | C16: =COUNTIF('Master Inventory'!C5:C444, "Anti Hypertensives") -> 14 | D16: =COUNTIFS('Master Inventory'!C5:C300, "Anti Hypertensives", 'Master Inventory'!N5:N300, "*REORDER*") -> 0
B17: Antibiotics | C17: =COUNTIF('Master Inventory'!C5:C444,"Antibiotics") -> 41 | D17: =COUNTIFS('Master Inventory'!C5:C300, "Antibiotics", 'Master Inventory'!N5:N300, "*REORDER*") -> 0
B18: Antiemetics | C18: =COUNTIF('Master Inventory'!C5:C444,"Antiemetics") -> 4 | D18: =COUNTIFS('Master Inventory'!C5:C300, "Antiemetics", 'Master Inventory'!N5:N300, "*REORDER*") -> 0
B19: Antifungals | C19: =COUNTIF('Master Inventory'!C5:C444, "Antifungals") -> 7 | D19: =COUNTIFS('Master Inventory'!C5:C300, "Antifungals", 'Master Inventory'!N5:N300, "*REORDER*") -> 0
B20: Antihistamines | C20: =COUNTIF('Master Inventory'!C5:C444, "Antihistamines") -> 22 | D20: =COUNTIFS('Master Inventory'!C5:C300, "Antihistamines", 'Master Inventory'!N5:N300, "*REORDER*") -> 0
B21: Antitussives | C21: =COUNTIF('Master Inventory'!C5:C444, "Antitussives") -> 37 | D21: =COUNTIFS('Master Inventory'!C5:C300, "Antitussives", 'Master Inventory'!N5:N300, "*REORDER*") -> 0
B22: Appetite & Vitamins | C22: =COUNTIF('Master Inventory'!C5:C444, "Appetite & Vitamins") -> 24 | D22: =COUNTIFS('Master Inventory'!C5:C300, "Appetite & Vitamins", 'Master Inventory'!N5:N300, "*REORDER*") -> 0
B23: Appetite Stimulants | C23: =COUNTIF('Master Inventory'!C5:C444, "Appetite Stimulants") -> 0 | D23: =COUNTIFS('Master Inventory'!C5:C300, "Appetite Stimulants", 'Master Inventory'!N5:N300, "*REORDER*") -> 0
B24: Blood Builders | C24: =COUNTIF('Master Inventory'!C5:C444, "Blood Builders") -> 4 | D24: =COUNTIFS('Master Inventory'!C5:C300, "Blood Builders", 'Master Inventory'!N5:N300, "*REORDER*") -> 0
B25: Creams & Topicals | C25: =COUNTIF('Master Inventory'!C5:C444, "Creams & Topicals") -> 32 | D25: =COUNTIFS('Master Inventory'!C5:C300, "Creams & Topicals", 'Master Inventory'!N5:N300, "*REORDER*") -> 0
B26: DM Drugs | C26: =COUNTIF('Master Inventory'!C5:C444, "DM Drugs") -> 8 | D26: =COUNTIFS('Master Inventory'!C5:C300, "DM Drugs", 'Master Inventory'!N5:N300, "*REORDER*") -> 0
B27: Dewormers & Gastro | C27: =COUNTIF('Master Inventory'!C5:C444, "Dewormers & Gastro") -> 25 | D27: =COUNTIFS('Master Inventory'!C5:C300, "Dewormers & Gastro", 'Master Inventory'!N5:N300, "*REORDER*") -> 0
B28: Diagnostic Gadgets | C28: =COUNTIF('Master Inventory'!C5:C444, "Diagnostic Gadgets") -> 5 | D28: =COUNTIFS('Master Inventory'!C5:C300, "Diagnostic Gadgets", 'Master Inventory'!N5:N300, "*REORDER*") -> 0
B29: Family Planning | C29: =COUNTIF('Master Inventory'!C5:C444, "Family Planning") -> 16 | D29: =COUNTIFS('Master Inventory'!C5:C300, "Family Planning", 'Master Inventory'!N5:N300, "*REORDER*") -> 0
B30: Fluids | C30: =COUNTIF('Master Inventory'!C5:C444, "Fluids") -> 5 | D30: =COUNTIFS('Master Inventory'!C5:C300, "Fluids", 'Master Inventory'!N5:N300, "*REORDER*") -> 0
B31: Injectables | C31: =COUNTIF('Master Inventory'!C5:C444, "Injectables") -> 13 | D31: =COUNTIFS('Master Inventory'!C5:C300, "Injectables", 'Master Inventory'!N5:N300, "*REORDER*") -> 0
B32: Lab Materials | C32: =COUNTIF('Master Inventory'!C5:C444,"Lab Materials") -> 13 | D32: =COUNTIFS('Master Inventory'!C5:C300, "Lab Materials", 'Master Inventory'!N5:N300, "*REORDER*") -> 0
B33: Ophthalmic & Otic | C33: =COUNTIF('Master Inventory'!C5:C300, "Ophthalmic & Otic") -> 13 | D33: =COUNTIFS('Master Inventory'!C5:C300, "Ophthalmic & Otic", 'Master Inventory'!N5:N300, "*REORDER*") -> 0
B34: Supplies & Consumables | C34: =COUNTIF('Master Inventory'!C5:C444, "Supplies & Consumables") -> 55 | D34: =COUNTIFS('Master Inventory'!C5:C300, "Supplies & Consumables", 'Master Inventory'!N5:N300, "*REORDER*") -> 0
B35: Supplies & Pharmasal spray | C35: =COUNTIF('Master Inventory'!C5:C444, "Supplies & Pharmasal spray") -> 0 | D35: =COUNTIFS('Master Inventory'!C5:C300, "Supplies & Pharmasal spray", 'Master Inventory'!N5:N300, "*REORDER*") -> 0
B36: Tablets Analgesic | C36: =COUNTIF('Master Inventory'!C5:C444, "Tablets Analgesic") -> 33 | D36: =COUNTIFS('Master Inventory'!C5:C300, "Tablets Analgesic", 'Master Inventory'!N5:N300, "*REORDER*") -> 0

Sheet Master Inventory
B2: Master Pharmaceutical Inventory Ledger
B4: Item ID | C4: Category | D4: Item Name | E4: Current Stock (Qty) | F4: Buying Price (KES) | G4: Selling Price (KES) | H4: Total Value (KES) | I4: Supplier | J4: Quantity | K4: Expiry Date | L4: Min Stock Level | M4: Status
B5: PH-1005 | C5: Antibiotics | D5: Amoxyl 250 mg caps | E5: 100 | F5: 170 | G5: 10 | H5: =E5*G5 -> 1000 | L5: 5 | M5: =IF(E5<=L5, "⚠️ REORDER", "✅ STABLE") -> ✅ STABLE
B6: PH-1006 | C6: Antibiotics | D6: Flucloxacylin syrup (floxapen) | E6: 5 | F6: 75 | G6: 150 | H6: =E6*G6 -> 750 | L6: 1 | M6: =IF(E6<=L6, "⚠️ REORDER", "✅ STABLE") -> ✅ STABLE
B7: PH-1007 | C7: Antibiotics | D7: Ampiclox syrup | E7: 5 | F7: 70 | G7: 150 | H7: =E7*G7 -> 750 | L7: 1 | M7: =IF(E7<=L7, "⚠️ REORDER", "✅ STABLE") -> ✅ STABLE
B8: PH-1008 | C8: Antibiotics | D8: Cefalexin syrup | E8: 5 | F8: 65 | G8: 300 | H8: =E8*G8 -> 1500 | L8: 1 | M8: =IF(E8<=L8, "⚠️ REORDER", "✅ STABLE") -> ✅ STABLE
B9: PH-1009 | C9: Antibiotics | D9: Cefixime syrup 60ml | E9: 2 | F9: 100 | G9: 300 | H9: =E9*G9 -> 600 | L9: 1 | M9: =IF(E9<=L9, "⚠️ REORDER", "✅ STABLE") -> ✅ STABLE
B10: PH-1010 | C10: Supplies & Consumables | D10: hydrogen peroxide | E10: 1 | F10: 25 | G10: 50 | H10: =E10*G10 -> 50 | L10: 1 | M10: =IF(E10<=L10, "⚠️ REORDER", "✅ STABLE") -> ⚠️ REORDER
B11: PH-1011 | C11: Antibiotics | D11: Azithromycin syrup 15ml | E11: 2 | F11: 50 | G11: 100 | H11: =E11*G11 -> 200 | L11: 2 | M11: =IF(E11<=L11, "⚠️ REORDER", "✅ STABLE") -> ⚠️ REORDER
B12: PH-1012 | C12: Appetite & Vitamins | D12: Seven seas cod liver oil capsule | E12: 10 | F12: 27 | G12: 40 | H12: =E12*G12 -> 400 | L12: 1 | M12: =IF(E12<=L12, "⚠️ REORDER", "✅ STABLE") -> ✅ STABLE
B13: PH-1013 | C13: Antibiotics | D13: Erythromycin syrup 100ml | E13: 4 | F13: 80 | G13: 150 | H13: =E13*G13 -> 600 | L13: 1 | M13: =IF(E13<=L13, "⚠️ REORDER", "✅ STABLE") -> ✅ STABLE
B14: PH-1014 | C14: Antibiotics | D14: Cefuroxime 250mg tabs | E14: 2 | F14: 155 | G14: 300 | H14: =E14*G14 -> 600 | L14: 0 | M14: =IF(E14<=L14, "⚠️ REORDER", "✅ STABLE") -> ✅ STABLE
B15: PH-1015 | C15: Antibiotics | D15: amoxyl 500mg caps | E15: 40 | F15: 300 | G15: 5 | H15: =E15*G15 -> 200 | L15: 5 | M15: =IF(E15<=L15, "⚠️ REORDER", "✅ STABLE") -> ✅ STABLE
B16: PH-1016 | C16: Antibiotics | D16: Amoxyl syrup 100mls | E16: 5 | F16: 50 | G16: 100 | H16: =E16*G16 -> 500 | L16: 1 | M16: =IF(E16<=L16, "⚠️ REORDER", "✅ STABLE") -> ✅ STABLE
... B44: PH-1044 | C44: Analgesic Syrup | D44: Paracetamol syrup 100ml (betamol) | E44: 7 | F44: 30 | G44: 100 | H44: =E44*G44 -> 700 | L44: 5 | M44: =IF(E44<=L44, "⚠️ REORDER", "✅ STABLE") -> ✅ STABLE
B45: PH-1045 | C45: Analgesic Syrup | D45: brufen syrup 60mls | E45: 0 | G45: 0 | H45: =E45*G45 -> 0 | L45: 1 | M45: =IF(E45<=L45, "⚠️ REORDER", "✅ STABLE") -> ⚠️ REORDER
B46: PH-1046 | C46: Analgesic Syrup | D46: Fevapyn 100ml (brufen syrup) | E46: 3 | F46: 45 | G46: 100 | H46: =E46*G46 -> 300 | L46: 1 | M46: =IF(E46<=L46, "⚠️ REORDER", "✅ STABLE") -> ✅ STABLE
B47: PH-1047 | C47: Anti Amoeba | D47: Metronidazole flaggyl 100ml | E47: 3 | F47: 40 | G47: 100 | H47: =E47*G47 -> 300 | L47: 1 | M47: =IF(E47<=L47, "⚠️ REORDER", "✅ STABLE") -> ✅ STABLE
B48: PH-1048 | C48: Anti Amoeba | D48: Eflaron plus syrup 100ml | E48: 1 | F48: 95 | G48: 200 | H48: =E48*G48 -> 200 | L48: 1 | M48: =IF(E48<=L48, "⚠️ REORDER", "✅ STABLE") -> ⚠️ REORDER
B49: PH-1049 | C49: Anti Amoeba | D49: Diracip syrup | E49: 0 | G49: 0 | H49: =E49*G49 -> 0 | L49: 1 | M49: =IF(E49<=L49, "⚠️ REORDER", "✅ STABLE") -> ⚠️ REORDER
B50: PH-1050 | C50: Anti Amoeba | D50: Enterozole | E50: 0 | G50: 0 | H50: =E50*G50 -> 0 | L50: 1 | M50: =IF(E50<=L50, "⚠️ REORDER", "✅ STABLE") -> ⚠️ REORDER
B51: PH-1051 | C51: Anti Amoeba | D51: Enterogemina | E51: 0 | G51: 0 | H51: =E51*G51 -> 0 | L51: 1 | M51: =IF(E51<=L51, "⚠️ REORDER", "✅ STABLE") -> ⚠️ REORDER
B52: PH-1052 | C52: Anti Amoeba | D52: Aminoxidine | E52: 0 | G52: 0 | H52: =E52*G52 -> 0 | L52: 1 | M52: =IF(E52<=L52, "⚠️ REORDER", "✅ STABLE") -> ⚠️ REORDER
B53: PH-1053 | C53: Anti Amoeba | D53: Secnidazole syrup (dysen 30ml ) | E53: 1 | F53: 125 | G53: 200 | H53: =E53*G53 -> 200 | L53: 1 | M53: =IF(E53<=L53, "⚠️ REORDER", "✅ STABLE") -> ⚠️ REORDER
B54: PH-1054 | C54: Anti Amoeba | D54: Flagyl d2 | E54: 0 | G54: 0 | H54: =E54*G54 -> 0 | L54: 1 | M54: =IF(E54<=L54, "⚠️ REORDER", "✅ STABLE") -> ⚠️ REORDER
B55: PH-1055 | C55: Anti Amoeba | D55: Flaggy metronidazole 200mg | E55: 90 | F55: 70 | G55: 5 | H55: =E55*G55 -> 450 | L55: 5 | M55: =IF(E55<=L55, "⚠️ REORDER", "✅ STABLE") -> ✅ STABLE
B56: PH-1056 | C56: Anti Amoeba | D56: Neopeptode | E56: 0 | G56: 0 | H56: =E56*G56 -> 0 | L56: 1 | M56: =IF(E56<=L56, "⚠️ REORDER", "✅ STABLE") -> ⚠️ REORDER
B57: PH-1057 | C57: Anti Amoeba | D57: G florax | E57: 0 | G57: 0 | H57: =E57*G57 -> 0 | L57: 1 | M57: =IF(E57<=L57, "⚠️ REORDER", "✅ STABLE") -> ⚠️ REORDER
B58: PH-1058 | C58: Antitussives | D58: Good morning | E58: 2 | F58: 85 | G58: 150 | H58: =E58*G58 -> 300 | L58: 1 | M58: =IF(E58<=L58, "⚠️ REORDER", "✅ STABLE") -> ✅ STABLE
B59: PH-1059 | C59: Antihistamines | D59: Cetrizine syrup (piricet) | E59: 7 | F59: 45 | G59: 100 | H59: =E59*G59 -> 700 | L59: 5 | M59: =IF(E59<=L59, "⚠️ REORDER", "✅ STABLE") -> ✅ STABLE
B60: PH-1060 | C60: Antitussives | D60: Chest cof syrup 100ml | E60: 2 | F60: 98 | G60: 150 | H60: =E60*G60 -> 300 | L60: 1 | M60: =IF(E60<=L60, "⚠️ REORDER", "✅ STABLE") -> ✅ STABLE
B61: PH-1061 | C61: Antitussives | D61: Thio carb 100ml | E61: 5 | F61: 60 | G61: 150 | H61: =E61*G61 -> 750 | L61: 1 | M61: =IF(E61<=L61, "⚠️ REORDER", "✅ STABLE") -> ✅ STABLE
B62: PH-1062 | C62: Antitussives | D62: Piriton chlopherinamine syrup (dawa) | E62: 20 | F62: 25 | G62: 50 | H62: =E62*G62 -> 1000 | L62: 5 | M62: =IF(E62<=L62, "⚠️ REORDER", "✅ STABLE") -> ✅ STABLE
B63: PH-1063 | C63: Antitussives | D63: Imacof expectorant 100ml | E63: 1 | F63: 90 | G63: 150 | H63: =E63*G63 -> 150 | L63: 1 | M63: =IF(E63<=L63, "⚠️ REORDER", "✅ STABLE") -> ⚠️ REORDER
B64: PH-1064 | C64: Antitussives | D64: Tripozed | E64: 0 | G64: 0 | H64: =E64*G64 -> 0 | L64: 1 | M64: =IF(E64<=L64, "⚠️ REORDER", "✅ STABLE") -> ⚠️ REORDER
B65: PH-1065 | C65: Antitussives | D65: Cetrihist expectorant 100ml | E65: 1 | F65: 46 | G65: 150 | H65: =E65*G65 -> 150 | L65: 1 | M65: =IF(E65<=L65, "⚠️ REORDER", "✅ STABLE") -> ⚠️ REORDER
B66: PH-1066 | C66: Antitussives | D66: Cetriplus | E66: 0 | G66: 0 | H66: =E66*G66 -> 0 | L66: 1 | M66: =IF(E66<=L66, "⚠️ REORDER", "✅ STABLE") -> ⚠️ REORDER
B67: PH-1067 | C67: Antitussives | D67: Tridex 60ml | E67: 0 | F67: 50 | G67: 100 | H67: =E67*G67 -> 0 | L67: 1 | M67: =IF(E67<=L67, "⚠️ REORDER", "✅ STABLE") -> ⚠️ REORDER
B68: PH-1068 | C68: Antitussives | D68: Alcof 100ml | E68: 3 | F68: 40 | G68: 150 | H68: =E68*G68 -> 450 | L68: 1 | M68: =IF(E68<=L68, "⚠️ REORDER", "✅ STABLE") -> ✅ STABLE
B69: PH-1069 | C69: Antitussives | D69: Lunahist cough syrup 100mls | E69: 3 | F69: 58 | G69: 150 | H69: =E69*G69 -> 450 | L69: 1 | M69: =IF(E69<=L69, "⚠️ REORDER", "✅ STABLE") -> ✅ STABLE
...

Sheet Sales
B2: Pharmacy Sales Ledger Tracking
B4: Invoice No | C4: Date | D4: Item ID | E4: Item Name | F4: Qty Sold | G4: Unit Price (KES) | H4: Gross Amount (KES) | I4: Unit COG | J4: Gross COG (KES) | K4: Net Profit (KES)
B5: =IF(ISBLANK(B2), "", COUNTA($B$2:B2)) -> 1 | C5: 27/06/2026 | E5: Cprofloxacin eye drops | F5: 1 | G5: 150 | H5: =F5*G5 -> 150 | I5: 110 | J5: =F5*I5 -> 110 | K5: =H5-J5 -> 40
B6: 2 | E6: omeprazole | F6: 2 | G6: 5 | H6: =F6*G6 -> 10 | I6: 0.9 | J6: =F6*I6 -> 1.8 | K6: =H6-J6 -> 8.2
B7: 3 | E7: Azythromycin | F7: 1 | G7: 100 | H7: =F7*G7 -> 100 | I7: 50 | J7: =F7*I7 -> 50 | K7: =H7-J7 -> 50
B8: 4 | E8: brufen tabs | F8: 10 | G8: 3 | H8: =F8*G8 -> 30 | I8: 1.3 | J8: =F8*I8 -> 13 | K8: =H8-J8 -> 17
B9: 5 | C9: 28/06/2026 | E9: mara moja | F9: 1 | G9: 10 | H9: =F9*G9 -> 10 | I9: 7 | J9: =F9*I9 -> 7 | K9: =H9-J9 -> 3
B10: 6 | E10: lobak | F10: 10 | G10: 20 | H10: =F10*G10 -> 200 | I10: 10 | J10: =F10*I10 -> 100 | K10: =H10-J10 -> 100
B11: 7 | E11: trust classic | F11: 1 | G11: 50 | H11: =F11*G11 -> 50 | I11: 26 | J11: =F11*I11 -> 26 | K11: =H11-J11 -> 24
E12: apc | F12: 10 | G12: 2 | H12: =F12*G12 -> 20 | I12: 1.2 | J12: =F12*I12 -> 12 | K12: =H12-J12 -> 8
C13: 29/06/2026 | E13: doxycycline | F13: 10 | G13: 10 | H13: =F13*G13 -> 100 | I13: 2.1 | J13: =F13*I13 -> 21 | K13: =H13-J13 -> 79
E14: amoxyl | F14: 15 | G14: 6.7 | H14: =F14*G14 -> 100.5 | I14: 3 | J14: =F14*I14 -> 45 | K14: =H14-J14 -> 55.5
E15: pcm | F15: 10 | G15: 2 | H15: =F15*G15 -> 20 | I15: 0.9 | J15: =F15*I15 -> 9 | K15: =H15-J15 -> 11
E16: hydrocortisone cream | F16: 1 | G16: 100 | H16: =F16*G16 -> 100 | I16: 28 | J16: =F16*I16 -> 28 | K16: =H16-J16 -> 72
E17: amoxyl | F17: 15 | G17: 6.6 | H17: =F17*G17 -> 99 | I17: 3 | J17: =F17*I17 -> 45 | K17: =H17-J17 -> 54
E18: piroxicam | F18: 10 | G18: 5 | H18: =F18*G18 -> 50 | I18: 0.85 | J18: =F18*I18 -> 8.5 | K18: =H18-J18 -> 41.5
C19: 30/06/2026 | E19: omeprazole | F19: 2 | G19: 5 | H19: =F19*G19 -> 10 | I19: 0.9 | J19: =F19*I19 -> 1.8 | K19: =H19-J19 -> 8.2
E20: montelucast | F20: 1 | G20: 25 | H20: =F20*G20 -> 25 | I20: 10.5 | J20: =F20*I20 -> 10.5 | K20: =H20-J20 -> 14.5
E21: maramoja | F21: 2 | G21: 10 | H21: =F21*G21 -> 20 | I21: 7 | J21: =F21*I21 -> 14 | K21: =H21-J21 -> 6
E22: cold caps | F22: 2 | G22: 20 | H22: =F22*G22 -> 40 | I22: 8 | J22: =F22*I22 -> 16 | K22: =H22-J22 -> 24
E23: cetrizine | F23: 2 | G23: 5 | H23: =F23*G23 -> 10 | I23: 0.9 | J23: =F23*I23 -> 1.8 | K23: =H23-J23 -> 8.2
E24: floxapen | F24: 20 | G24: 12.5 | H24: =F24*G24 -> 250 | I24: 6.7 | J24: =F24*I24 -> 134 | K24: =H24-J24 -> 116
E25: omeprazole | F25: 4 | G25: 5 | H25: =F25*G25 -> 20 | I25: 0.9 | J25: =F25*I25 -> 3.6 | K25: =H25-J25 -> 16.4
E26: apc | F26: 5 | G26: 2 | H26: =F26*G26 -> 10 | I26: 1.2 | J26: =F26*I26 -> 6 | K26: =H26-J26 -> 4
E27: cetrizine | F27: 2 | G27: 5 | H27: =F27*G27 -> 10 | I27: 0.9 | J27: =F27*I27 -> 1.8 | K27: =H27-J27 -> 8.2
E28: maramoja | F28: 1 | G28: 10 | H28: =F28*G28 -> 10 | I28: 7 | J28: =F28*I28 -> 7 | K28: =H28-J28 -> 3
C29: 46029 | E29: omeprazole | F29: 8 | G29: 5 | H29: =F29*G29 -> 40 | I29: 0.9 | J29: =F29*I29 -> 7.2 | K29: =H29-J29 -> 32.8
E30: omeprazole | F30: 2 | G30: 5 | H30: =F30*G30 -> 10 | I30: 0.9 | J30: =F30*I30 -> 1.8 | K30: =H30-J30 -> 8.2
C31: 46060 | E31: omeprazole | F31: 2 | G31: 5 | H31: =F31*G31 -> 10 | I31: 0.9 | J31: =F31*I31 -> 1.8 | K31: =H31-J31 -> 8.2
E32: montelucast | F32: 1 | G32: 25 | H32: =F32*G32 -> 25 | I32: 10.5 | J32: =F32*I32 -> 10.5 | K32: =H32-J32 -> 14.5
E33: maramoja | F33: 1 | G33: 10 | H33: =F33*G33 -> 10 | I33: 7 | J33: =F33*I33 -> 7 | K33: =H33-J33 -> 3
E34: eno | F34: 1 | G34: 20 | H34: =F34*G34 -> 20 | I34: 17 | J34: =F34*I34 -> 17 | K34: =H34-J34 -> 3
E35: omeprazole | F35: 2 | G35: 5 | H35: =F35*G35 -> 10 | I35: 0.9 | J35: =F35*I35 -> 1.8 | K35: =H35-J35 -> 8.2
E36: kaluma lozzonges | F36: 1 | G36: 20 | H36: =F36*G36 -> 20 | I36: 12 | J36: =F36*I36 -> 12 | K36: =H36-J36 -> 8
E37: kaluma tablets | F37: 1 | G37: 10 | H37: =F37*G37 -> 10 | I37: 6 | J37: =F37*I37 -> 6 | K37: =H37-J37 -> 4
E38: amoxyl | F38: 5 | G38: 10 | H38: =F38*G38 -> 50 | I38: 3 | J38: =F38*I38 -> 15 | K38: =H38-J38 -> 35
E39: prednisolone | F39: 10 | G39: 2 | H39: =F39*G39 -> 20 | I39: 0.65 | J39: =F39*I39 -> 6.5 | K39: =H39-J39 -> 13.5
C40: 46088 | E40: promethazine | F40: 4 | G40: 5 | H40: =F40*G40 -> 20 | I40: 1.9 | J40: =F40*I40 -> 7.6 | K40: =H40-J40 -> 12.4
E41: celestamine | F41: 1 | G41: 20 | H41: =F41*G41 -> 20 | I41: 8.8 | J41: =F41*I41 -> 8.8 | K41: =H41-J41 -> 11.2
E42: pcm | F42: 10 | G42: 2 | H42: =F42*G42 -> 20 | I42: 0.9 | J42: =F42*I42 -> 9 | K42: =H42-J42 -> 11
...

Sheet Transactions
B2: Pharmacy Transactions Ledger Tracking
B4: Expenditure ID | C4: Date | D4: Money IN/profits | E4: Item Name | F4: Money OUT/Expenditure | G4: Quantity | H4: User Account | I4: Verified By
B5: JULY total monthly earnings | C5: 31/07/2026 | D5: 22397
B6: july rent | C6: 20/07/2026 | F6: 8000
B7: July electricity bill | F7: 600
B8: July wifi bill
B9: july salary payments | F9: 6000
B10: Restocking amount | D10: 11150 | F10: 10109
B11: July net profit | C11: 31/07/2026 | D11: 11248
B13: August total restocking cost
B14: August shop rent
B15: August electricity bill
B16: August salary payments
B17: August

Sheet Purchase Orders
B2: Pharmacy Purchase Orders Ledger Tracking
B4: Item | C4: Date purchase | D4: Supplier Amount | E4: Item Required | F4: Order Qty | G4: Estimated Unit Cost | H4: Delivery Window Status
B5: RSTOCKING OUT OF STOCK ITEMS | D5: 2450
B6: RESTOCKING OUT OF STOCK ITEMS | C6: 20/07/2026 | D6: 2092
B7: RESTOCKING OUT OF STOCK ITEMS | C7: 14/07/2026 | D7: 1052
B8: RESTOCKING OUT OF STOCK ITEMS | C8: 30/07/2026 | D8: 630
B9: RESTOCKING OUT OF STOCK ITEMS | C9: 29/07/2025 | D9: 190
B10: RESTOCKING OUT OF STOCK ITEMS | C10: 13/07/2025 | D10: 600
B11: RESTOCKING OUT OF STOCK ITEMS | C11: 28/07/2025 | D11: 1930
B12: TOTAL july restocking Expenditure | D12: =SUM(D4:D11) -> 8944
B13: AUGUST EXPENDITURE
B14: HOUSE RENT | C14: 46181 | D14: 6000
B15: Restocking of drugs that were OS | C15: 46181 | D15: 1165
B16: House Shopping | C16: 46089 | D16: 3000
B17: Restocking of drugs that were OS | C17: 15/08/2026 | D17: 2300
B18: printing and setting direction poster | C18: 20/08/2026 | D18: 1000
B19: Restocking of drugs that were OS | C19: 20/08/2026 | D19: 960
B20: refilling water | C20: 21/08/2026 | D20: 250

Sheet Suppliers
B2: Pharmacy Suppliers Ledger Tracking
B4: Supplier ID | C4: Company Name | D4: Contact Person | E4: Phone Number | F4: Email Address | G4: Tax ID / PIN | H4: Outstanding Balance (KES)

Sheet DDA Register
B2: Pharmacy DDA Register Ledger Tracking
B4: DDA Log Ref | C4: Date | D4: Item ID (Controlled) | E4: Patient Name | F4: Prescribing Doctor | G4: Qty Dispensed | H4: Doctor License No | I4: Pharmacist Signature

Sheet Expiry Register
B2: Pharmacy Expiry Register Ledger Tracking
B4: Log ID | C4: Item ID | D4: Item Name | E4: Batch Number | F4: Expiry Date | G4: Days Remaining | H4: Risk Severity Status
G5: =F5-TODAY() -> -46270 | H5: =IF(G5<=0,"❌ EXPIRED",IF(G5<=90,"⚠️ CRITICAL","✅ SAFE")) -> ❌ EXPIRED

Sheet Stock Take
B2: Pharmacy Stock Take Ledger Tracking
B4: Audit Date | C4: Item ID | D4: Item Name | E4: System Qty | F4: Physical Counted Qty | G4: Variance Qty | H4: Financial Discrepancy | I4: Action Taken
G5: =F5-E5 -> 0 | H5: =G5*'Master Inventory'!F5 -> 0
